Workbook

Sheet Titles
A2: Housing Start Data in Centres 10,000 Population and Over
A4: December 2020 - 2021
A5: January - December 2020 - 2021
A7: Footnotes
A8: Data for 2020 and 2021 based on 2016 Census Definitions.
A10: Source: CMHC Starts and Completion Survey, Market Absorption Survey
A12: 1 Data for 2020 and 2021 based on 2016 Census Definitions.
A14: 2021 based on 2016 Census Definitions.
A18: Données révisées sur les mises en chantier d'habitations
A19: Données provisoires sur les mises en chantier d'habitations
A20: Données provisoires sur les mises en chantier d'habitations
A21: révisées
A22: provisoires

Sheet Index
B1: CMHC HOUSING MARKET INFORMATION
B2: Monthly Housing Starts and Other Construction Data
B4: Source: CMHC Starts and Completions Survey and Market Absorption Survey
B5: © 2021 Canada Mortgage and Housing Corporation
B7: TABLE OF CONTENTS
B8: The table of contents below provides a brief description of the contents in each tab.
B10: Note to readers
B12: Table 1: Housing Start Data in Centres 10,000 Population and Over
B14: Table 2: Housing Start Data in Centres 10,000 Population and Over (Cumulative)
B16: Table 3: Dwelling Starts in Urban Centres and Canada, Seasonally Adjusted at Annual Rates
B18: Table 4: Dwelling Starts in Urban Centres, by Region, Seasonally Adjusted at Annual Rates
B20: Table 5: Dwelling Starts in Urban Centres, by Region, Seasonally Adjusted at Annual Rates
... B40: Type of Dwelling

Sheet Notes
A1: Note to readers impact of COVID-19 on data collection efforts:
A2: *CMHC’s Starts and Completions Survey (SCS) for April was conducted in each province with the exception of Québec as residential construction activity was halted in the province during the period from March 25 to April 12, 2020.
A3: *In addition, in December 2020, SCS was not conducted in Kelowna CMA.
A5: *Due to the flood situation in British Columbia, CMHC was not able to administer SCS in Chilliwack CA for November 2021

Sheet Table 1
A1: Table 1
A2: =Titles!A2 -> Housing Start Data in Centres 10,000 Population and Over
A4: =Titles!A4 -> December 2020 - 2021
A5: Area | C5: Single-Detached | F5: All Others | I5: Total
A6: Province
C7: 2020 | D7: 2021 | E7: % | F7: 2020 | G7: 2021 | H7: % | I7: 2020 | J7: 2021 | K7: %
A8: Nfld.Lab. | C8: 53 | D8: 56 | E8: =IF(C8=D8,"-",IF((C8=0),"##",IF(ABS((D8/C8-1)*100)>=500,"##",(D8/C8-1)*100))) -> 5.6603774 | F8: 7 | G8: 24 | H8: =IF(F8=G8,"-",IF((F8=0),"##",IF(ABS((G8/F8-1)*100)>=500,"##",(G8/F8-1)*100))) -> 242.85714 | I8: =C8+F8 -> 60 | J8: =D8+G8 -> 80 | K8: =IF(I8=J8,"-",IF((I8=0),"##",IF(ABS((J8/I8-1)*100)>=500,"##",(J8/I8-1)*100))) -> 33.333333
A9: P.E.I. | C9: 18 | D9: 19 | E9: =IF(C9=D9,"-",IF((C9=0),"##",IF(ABS((D9/C9-1)*100)>=500,"##",(D9/C9-1)*100))) -> 5.5555556 | F9: 11 | G9: 19 | H9: =IF(F9=G9,"-",IF((F9=0),"##",IF(ABS((G9/F9-1)*100)>=500,"##",(G9/F9-1)*100))) -> 72.727273 | I9: =C9+F9 -> 29 | J9: =D9+G9 -> 38 | K9: =IF(I9=J9,"-",IF((I9=0),"##",IF(ABS((J9/I9-1)*100)>=500,"##",(J9/I9-1)*100))) -> 31.034483
A10: N.S. | C10: 143 | D10: 149 | E10: =IF(C10=D10,"-",IF((C10=0),"##",IF(ABS((D10/C10-1)*100)>=500,"##",(D10/C10-1)*100))) -> 4.1958042 | F10: 353 | G10: 607 | H10: =IF(F10=G10,"-",IF((F10=0),"##",IF(ABS((G10/F10-1)*100)>=500,"##",(G10/F10-1)*100))) -> 71.954674 | I10: =C10+F10 -> 496 | J10: =D10+G10 -> 756 | K10: =IF(I10=J10,"-",IF((I10=0),"##",IF(ABS((J10/I10-1)*100)>=500,"##",(J10/I10-1)*100))) -> 52.419355
A11: N.B. | C11: 77 | D11: 79 | E11: =IF(C11=D11,"-",IF((C11=0),"##",IF(ABS((D11/C11-1)*100)>=500,"##",(D11/C11-1)*100))) -> 2.5974026 | F11: 434 | G11: 266 | H11: =IF(F11=G11,"-",IF((F11=0),"##",IF(ABS((G11/F11-1)*100)>=500,"##",(G11/F11-1)*100))) -> -38.709677 | I11: =C11+F11 -> 511 | J11: =D11+G11 -> 345 | K11: =IF(I11=J11,"-",IF((I11=0),"##",IF(ABS((J11/I11-1)*100)>=500,"##",(J11/I11-1)*100))) -> -32.485323
A12: Atlantic | C12: =SUM(C8:C11) -> 291 | D12: =SUM(D8:D11) -> 303 | E12: =IF(C12=D12,"-",IF((C12=0),"##",IF(ABS((D12/C12-1)*100)>=500,"##",(D12/C12-1)*100))) -> 4.1237113 | F12: =SUM(F8:F11) -> 805 | G12: =SUM(G8:G11) -> 916 | H12: =IF(F12=G12,"-",IF((F12=0),"##",IF(ABS((G12/F12-1)*100)>=500,"##",(G12/F12-1)*100))) -> 13.78882 | I12: =C12+F12 -> 1096 | J12: =D12+G12 -> 1219 | K12: =IF(I12=J12,"-",IF((I12=0),"##",IF(ABS((J12/I12-1)*100)>=500,"##",(J12/I12-1)*100))) -> 11.222628
A13: Que. | C13: 583 | D13: 344 | E13: =IF(C13=D13,"-",IF((C13=0),"##",IF(ABS((D13/C13-1)*100)>=500,"##",(D13/C13-1)*100))) -> -40.994854 | F13: 3952 | G13: 3274 | H13: =IF(F13=G13,"-",IF((F13=0),"##",IF(ABS((G13/F13-1)*100)>=500,"##",(G13/F13-1)*100))) -> -17.15587 | I13: =C13+F13 -> 4535 | J13: =D13+G13 -> 3618 | K13: =IF(I13=J13,"-",IF((I13=0),"##",IF(ABS((J13/I13-1)*100)>=500,"##",(J13/I13-1)*100))) -> -20.220507
A14: Ont. | C14: 1700 | D14: 1870 | E14: =IF(C14=D14,"-",IF((C14=0),"##",IF(ABS((D14/C14-1)*100)>=500,"##",(D14/C14-1)*100))) -> 10 | F14: 3989 | G14: 3576 | H14: =IF(F14=G14,"-",IF((F14=0),"##",IF(ABS((G14/F14-1)*100)>=500,"##",(G14/F14-1)*100))) -> -10.353472 | I14: =C14+F14 -> 5689 | J14: =D14+G14 -> 5446 | K14: =IF(I14=J14,"-",IF((I14=0),"##",IF(ABS((J14/I14-1)*100)>=500,"##",(J14/I14-1)*100))) -> -4.2714009
A15: Man. | C15: 174 | D15: 187 | E15: =IF(C15=D15,"-",IF((C15=0),"##",IF(ABS((D15/C15-1)*100)>=500,"##",(D15/C15-1)*100))) -> 7.4712644 | F15: 336 | G15: 374 | H15: =IF(F15=G15,"-",IF((F15=0),"##",IF(ABS((G15/F15-1)*100)>=500,"##",(G15/F15-1)*100))) -> 11.309524 | I15: =C15+F15 -> 510 | J15: =D15+G15 -> 561 | K15: =IF(I15=J15,"-",IF((I15=0),"##",IF(ABS((J15/I15-1)*100)>=500,"##",(J15/I15-1)*100))) -> 10
A16: Sask. | C16: 137 | D16: 125 | E16: =IF(C16=D16,"-",IF((C16=0),"##",IF(ABS((D16/C16-1)*100)>=500,"##",(D16/C16-1)*100))) -> -8.7591241 | F16: 128 | G16: 128 | H16: =IF(F16=G16,"-",IF((F16=0),"##",IF(ABS((G16/F16-1)*100)>=500,"##",(G16/F16-1)*100))) -> - | I16: =C16+F16 -> 265 | J16: =D16+G16 -> 253 | K16: =IF(I16=J16,"-",IF((I16=0),"##",IF(ABS((J16/I16-1)*100)>=500,"##",(J16/I16-1)*100))) -> -4.5283019
A17: Alta. | C17: 914 | D17: 1104 | E17: =IF(C17=D17,"-",IF((C17=0),"##",IF(ABS((D17/C17-1)*100)>=500,"##",(D17/C17-1)*100))) -> 20.787746 | F17: 1525 | G17: 1398 | H17: =IF(F17=G17,"-",IF((F17=0),"##",IF(ABS((G17/F17-1)*100)>=500,"##",(G17/F17-1)*100))) -> -8.3278689 | I17: =C17+F17 -> 2439 | J17: =D17+G17 -> 2502 | K17: =IF(I17=J17,"-",IF((I17=0),"##",IF(ABS((J17/I17-1)*100)>=500,"##",(J17/I17-1)*100))) -> 2.5830258
A18: Prairies | C18: =SUM(C15:C17) -> 1225 | D18: =SUM(D15:D17) -> 1416 | E18: =IF(C18=D18,"-",IF((C18=0),"##",IF(ABS((D18/C18-1)*100)>=500,"##",(D18/C18-1)*100))) -> 15.591837 | F18: =SUM(F15:F17) -> 1989 | G18: =SUM(G15:G17) -> 1900 | H18: =IF(F18=G18,"-",IF((F18=0),"##",IF(ABS((G18/F18-1)*100)>=500,"##",(G18/F18-1)*100))) -> -4.4746104 | I18: =C18+F18 -> 3214 | J18: =D18+G18 -> 3316 | K18: =IF(I18=J18,"-",IF((I18=0),"##",IF(ABS((J18/I18-1)*100)>=500,"##",(J18/I18-1)*100))) -> 3.1736154
A19: B.C. | C19: 536 | D19: 679 | E19: =IF(C19=D19,"-",IF((C19=0),"##",IF(ABS((D19/C19-1)*100)>=500,"##",(D19/C19-1)*100))) -> 26.679104 | F19: 2714 | G19: 3519 | H19: =IF(F19=G19,"-",IF((F19=0),"##",IF(ABS((G19/F19-1)*100)>=500,"##",(G19/F19-1)*100))) -> 29.661017 | I19: =C19+F19 -> 3250 | J19: =D19+G19 -> 4198 | K19: =IF(I19=J19,"-",IF((I19=0),"##",IF(ABS((J19/I19-1)*100)>=500,"##",(J19/I19-1)*100))) -> 29.169231
A20: Canada | C20: =SUM(C12:C14,C18:C19) -> 4335 | D20: =SUM(D12:D14,D18:D19) -> 4612 | E20: =IF(C20=D20,"-",IF((C20=0),"##",IF(ABS((D20/C20-1)*100)>=500,"##",(D20/C20-1)*100))) -> 6.3898501 | F20: =SUM(F12:F14,F18:F19) -> 13449 | G20: =SUM(G12:G14,G18:G19) -> 13185 | H20: =IF(F20=G20,"-",IF((F20=0),"##",IF(ABS((G20/F20-1)*100)>=500,"##",(G20/F20-1)*100))) -> -1.9629712 | I20: =C20+F20 -> 17784 | J20: =D20+G20 -> 17797 | K20: =IF(I20=J20,"-",IF((I20=0),"##",IF(ABS((J20/I20-1)*100)>=500,"##",(J20/I20-1)*100))) -> 0.073099415
A21: Metropolitan Areas
A23: Abbotsford-Mission | C23: 30 | D23: 18 | E23: =IF(C23=D23,"-",IF((C23=0),"##",IF(ABS((D23/C23-1)*100)>=500,"##",(D23/C23-1)*100))) -> -40 | F23: 13 | G23: 165 | H23: =IF(F23=G23,"-",IF((F23=0),"##",IF(ABS((G23/F23-1)*100)>=500,"##",(G23/F23-1)*100))) -> ## | I23: =C23+F23 -> 43 | J23: =D23+G23 -> 183 | K23: =IF(I23=J23,"-",IF((I23=0),"##",IF(ABS((J23/I23-1)*100)>=500,"##",(J23/I23-1)*100))) -> 325.5814
A24: Barrie | C24: 34 | D24: 90 | E24: =IF(C24=D24,"-",IF((C24=0),"##",IF(ABS((D24/C24-1)*100)>=500,"##",(D24/C24-1)*100))) -> 164.70588 | F24: 6 | G24: 62 | H24: =IF(F24=G24,"-",IF((F24=0),"##",IF(ABS((G24/F24-1)*100)>=500,"##",(G24/F24-1)*100))) -> ## | I24: =C24+F24 -> 40 | J24: =D24+G24 -> 152 | K24: =IF(I24=J24,"-",IF((I24=0),"##",IF(ABS((J24/I24-1)*100)>=500,"##",(J24/I24-1)*100))) -> 280
A25: Belleville | C25: 37 | D25: 25 | E25: =IF(C25=D25,"-",IF((C25=0),"##",IF(ABS((D25/C25-1)*100)>=500,"##",(D25/C25-1)*100))) -> -32.432432 | F25: 14 | G25: 8 | H25: =IF(F25=G25,"-",IF((F25=0),"##",IF(ABS((G25/F25-1)*100)>=500,"##",(G25/F25-1)*100))) -> -42.857143 | I25: =C25+F25 -> 51 | J25: =D25+G25 -> 33 | K25: =IF(I25=J25,"-",IF((I25=0),"##",IF(ABS((J25/I25-1)*100)>=500,"##",(J25/I25-1)*100))) -> -35.294118
A26: Brantford | C26: 31 | D26: 153 | E26: =IF(C26=D26,"-",IF((C26=0),"##",IF(ABS((D26/C26-1)*100)>=500,"##",(D26/C26-1)*100))) -> 393.54839 | F26: 81 | G26: 2 | H26: =IF(F26=G26,"-",IF((F26=0),"##",IF(ABS((G26/F26-1)*100)>=500,"##",(G26/F26-1)*100))) -> -97.530864 | I26: =C26+F26 -> 112 | J26: =D26+G26 -> 155 | K26: =IF(I26=J26,"-",IF((I26=0),"##",IF(ABS((J26/I26-1)*100)>=500,"##",(J26/I26-1)*100))) -> 38.392857
A27: Calgary | C27: 402 | D27: 473 | E27: =IF(C27=D27,"-",IF((C27=0),"##",IF(ABS((D27/C27-1)*100)>=500,"##",(D27/C27-1)*100))) -> 17.661692 | F27: 438 | G27: 682 | H27: =IF(F27=G27,"-",IF((F27=0),"##",IF(ABS((G27/F27-1)*100)>=500,"##",(G27/F27-1)*100))) -> 55.707763 | I27: =C27+F27 -> 840 | J27: =D27+G27 -> 1155 | K27: =IF(I27=J27,"-",IF((I27=0),"##",IF(ABS((J27/I27-1)*100)>=500,"##",(J27/I27-1)*100))) -> 37.5
A28: Edmonton | C28: 377 | D28: 445 | E28: =IF(C28=D28,"-",IF((C28=0),"##",IF(ABS((D28/C28-1)*100)>=500,"##",(D28/C28-1)*100))) -> 18.037135 | F28: 1009 | G28: 615 | H28: =IF(F28=G28,"-",IF((F28=0),"##",IF(ABS((G28/F28-1)*100)>=500,"##",(G28/F28-1)*100))) -> -39.048563 | I28: =C28+F28 -> 1386 | J28: =D28+G28 -> 1060 | K28: =IF(I28=J28,"-",IF((I28=0),"##",IF(ABS((J28/I28-1)*100)>=500,"##",(J28/I28-1)*100))) -> -23.520924
A29: Greater/Grand Sudbury | C29: 6 | D29: 8 | E29: =IF(C29=D29,"-",IF((C29=0),"##",IF(ABS((D29/C29-1)*100)>=500,"##",(D29/C29-1)*100))) -> 33.333333 | F29: 8 | G29: 4 | H29: =IF(F29=G29,"-",IF((F29=0),"##",IF(ABS((G29/F29-1)*100)>=500,"##",(G29/F29-1)*100))) -> -50 | I29: =C29+F29 -> 14 | J29: =D29+G29 -> 12 | K29: =IF(I29=J29,"-",IF((I29=0),"##",IF(ABS((J29/I29-1)*100)>=500,"##",(J29/I29-1)*100))) -> -14.285714
A30: Guelph | C30: 21 | D30: 8 | E30: =IF(C30=D30,"-",IF((C30=0),"##",IF(ABS((D30/C30-1)*100)>=500,"##",(D30/C30-1)*100))) -> -61.904762 | F30: 87 | G30: 32 | H30: =IF(F30=G30,"-",IF((F30=0),"##",IF(ABS((G30/F30-1)*100)>=500,"##",(G30/F30-1)*100))) -> -63.218391 | I30: =C30+F30 -> 108 | J30: =D30+G30 -> 40 | K30: =IF(I30=J30,"-",IF((I30=0),"##",IF(ABS((J30/I30-1)*100)>=500,"##",(J30/I30-1)*100))) -> -62.962963
A31: Halifax | C31: 75 | D31: 86 | E31: =IF(C31=D31,"-",IF((C31=0),"##",IF(ABS((D31/C31-1)*100)>=500,"##",(D31/C31-1)*100))) -> 14.666667 | F31: 253 | G31: 495 | H31: =IF(F31=G31,"-",IF((F31=0),"##",IF(ABS((G31/F31-1)*100)>=500,"##",(G31/F31-1)*100))) -> 95.652174 | I31: =C31+F31 -> 328 | J31: =D31+G31 -> 581 | K31: =IF(I31=J31,"-",IF((I31=0),"##",IF(ABS((J31/I31-1)*100)>=500,"##",(J31/I31-1)*100))) -> 77.134146
A32: Hamilton | C32: 45 | D32: 41 | E32: =IF(C32=D32,"-",IF((C32=0),"##",IF(ABS((D32/C32-1)*100)>=500,"##",(D32/C32-1)*100))) -> -8.8888889 | F32: 281 | G32: 261 | H32: =IF(F32=G32,"-",IF((F32=0),"##",IF(ABS((G32/F32-1)*100)>=500,"##",(G32/F32-1)*100))) -> -7.1174377 | I32: =C32+F32 -> 326 | J32: =D32+G32 -> 302 | K32: =IF(I32=J32,"-",IF((I32=0),"##",IF(ABS((J32/I32-1)*100)>=500,"##",(J32/I32-1)*100))) -> -7.3619632
A33: Kelowna | C33: 0 | D33: 106 | E33: =IF(C33=D33,"-",IF((C33=0),"##",IF(ABS((D33/C33-1)*100)>=500,"##",(D33/C33-1)*100))) -> ## | F33: 0 | G33: 457 | H33: =IF(F33=G33,"-",IF((F33=0),"##",IF(ABS((G33/F33-1)*100)>=500,"##",(G33/F33-1)*100))) -> ## | I33: =C33+F33 -> 0 | J33: =D33+G33 -> 563 | K33: =IF(I33=J33,"-",IF((I33=0),"##",IF(ABS((J33/I33-1)*100)>=500,"##",(J33/I33-1)*100))) -> ##
A34: Kingston | C34: 20 | D34: 28 | E34: =IF(C34=D34,"-",IF((C34=0),"##",IF(ABS((D34/C34-1)*100)>=500,"##",(D34/C34-1)*100))) -> 40 | F34: 37 | G34: 17 | H34: =IF(F34=G34,"-",IF((F34=0),"##",IF(ABS((G34/F34-1)*100)>=500,"##",(G34/F34-1)*100))) -> -54.054054 | I34: =C34+F34 -> 57 | J34: =D34+G34 -> 45 | K34: =IF(I34=J34,"-",IF((I34=0),"##",IF(ABS((J34/I34-1)*100)>=500,"##",(J34/I34-1)*100))) -> -21.052632
... A40: Oshawa | C40: 67 | D40: 33 | E40: =IF(C40=D40,"-",IF((C40=0),"##",IF(ABS((D40/C40-1)*100)>=500,"##",(D40/C40-1)*100))) -> -50.746269 | F40: 97 | G40: 19 | H40: =IF(F40=G40,"-",IF((F40=0),"##",IF(ABS((G40/F40-1)*100)>=500,"##",(G40/F40-1)*100))) -> -80.412371 | I40: =C40+F40 -> 164 | J40: =D40+G40 -> 52 | K40: =IF(I40=J40,"-",IF((I40=0),"##",IF(ABS((J40/I40-1)*100)>=500,"##",(J40/I40-1)*100))) -> -68.292683
A41: Ottawa-Gatineau | C41: =SUM(C42:C43) -> 262 | D41: =SUM(D42:D43) -> 223 | E41: =IF(C41=D41,"-",IF((C41=0),"##",IF(ABS((D41/C41-1)*100)>=500,"##",(D41/C41-1)*100))) -> -14.885496 | F41: =SUM(F42:F43) -> 812 | G41: =SUM(G42:G43) -> 170 | H41: =IF(F41=G41,"-",IF((F41=0),"##",IF(ABS((G41/F41-1)*100)>=500,"##",(G41/F41-1)*100))) -> -79.064039 | I41: =C41+F41 -> 1074 | J41: =D41+G41 -> 393 | K41: =IF(I41=J41,"-",IF((I41=0),"##",IF(ABS((J41/I41-1)*100)>=500,"##",(J41/I41-1)*100))) -> -63.407821
A42: Gatineau | C42: 59 | D42: 17 | E42: =IF(C42=D42,"-",IF((C42=0),"##",IF(ABS((D42/C42-1)*100)>=500,"##",(D42/C42-1)*100))) -> -71.186441 | F42: 248 | G42: 11 | H42: =IF(F42=G42,"-",IF((F42=0),"##",IF(ABS((G42/F42-1)*100)>=500,"##",(G42/F42-1)*100))) -> -95.564516 | I42: =C42+F42 -> 307 | J42: =D42+G42 -> 28 | K42: =IF(I42=J42,"-",IF((I42=0),"##",IF(ABS((J42/I42-1)*100)>=500,"##",(J42/I42-1)*100))) -> -90.879479
A43: Ottawa | C43: 203 | D43: 206 | E43: =IF(C43=D43,"-",IF((C43=0),"##",IF(ABS((D43/C43-1)*100)>=500,"##",(D43/C43-1)*100))) -> 1.4778325 | F43: 564 | G43: 159 | H43: =IF(F43=G43,"-",IF((F43=0),"##",IF(ABS((G43/F43-1)*100)>=500,"##",(G43/F43-1)*100))) -> -71.808511 | I43: =C43+F43 -> 767 | J43: =D43+G43 -> 365 | K43: =IF(I43=J43,"-",IF((I43=0),"##",IF(ABS((J43/I43-1)*100)>=500,"##",(J43/I43-1)*100))) -> -52.411995
A44: Peterborough | C44: 25 | D44: 39 | E44: =IF(C44=D44,"-",IF((C44=0),"##",IF(ABS((D44/C44-1)*100)>=500,"##",(D44/C44-1)*100))) -> 56 | F44: 0 | G44: 0 | H44: =IF(F44=G44,"-",IF((F44=0),"##",IF(ABS((G44/F44-1)*100)>=500,"##",(G44/F44-1)*100))) -> - | I44: =C44+F44 -> 25 | J44: =D44+G44 -> 39 | K44: =IF(I44=J44,"-",IF((I44=0),"##",IF(ABS((J44/I44-1)*100)>=500,"##",(J44/I44-1)*100))) -> 56
A45: Québec | C45: 44 | D45: 50 | E45: =IF(C45=D45,"-",IF((C45=0),"##",IF(ABS((D45/C45-1)*100)>=500,"##",(D45/C45-1)*100))) -> 13.636364 | F45: 397 | G45: 605 | H45: =IF(F45=G45,"-",IF((F45=0),"##",IF(ABS((G45/F45-1)*100)>=500,"##",(G45/F45-1)*100))) -> 52.392947 | I45: =C45+F45 -> 441 | J45: =D45+G45 -> 655 | K45: =IF(I45=J45,"-",IF((I45=0),"##",IF(ABS((J45/I45-1)*100)>=500,"##",(J45/I45-1)*100))) -> 48.526077
A46: Regina | C46: 47 | D46: 33 | E46: =IF(C46=D46,"-",IF((C46=0),"##",IF(ABS((D46/C46-1)*100)>=500,"##",(D46/C46-1)*100))) -> -29.787234 | F46: 49 | G46: 56 | H46: =IF(F46=G46,"-",IF((F46=0),"##",IF(ABS((G46/F46-1)*100)>=500,"##",(G46/F46-1)*100))) -> 14.285714 | I46: =C46+F46 -> 96 | J46: =D46+G46 -> 89 | K46: =IF(I46=J46,"-",IF((I46=0),"##",IF(ABS((J46/I46-1)*100)>=500,"##",(J46/I46-1)*100))) -> -7.2916667
A47: Saguenay | C47: 22 | D47: 10 | E47: =IF(C47=D47,"-",IF((C47=0),"##",IF(ABS((D47/C47-1)*100)>=500,"##",(D47/C47-1)*100))) -> -54.545455 | F47: 64 | G47: 30 | H47: =IF(F47=G47,"-",IF((F47=0),"##",IF(ABS((G47/F47-1)*100)>=500,"##",(G47/F47-1)*100))) -> -53.125 | I47: =C47+F47 -> 86 | J47: =D47+G47 -> 40 | K47: =IF(I47=J47,"-",IF((I47=0),"##",IF(ABS((J47/I47-1)*100)>=500,"##",(J47/I47-1)*100))) -> -53.488372
...

Sheet Table 2
A1: Table 2
A2: =Titles!A2 -> Housing Start Data in Centres 10,000 Population and Over
A4: =Titles!A5 -> January - December 2020 - 2021
A5: Area | C5: Single-Detached | F5: All Others | I5: Total
A6: Province
C7: 2020 | D7: 2021 | E7: % | F7: 2020 | G7: 2021 | H7: % | I7: 2020 | J7: 2021 | K7: %
A8: Nfld.Lab. | C8: 407 | D8: 492 | E8: =IF(C8=D8,"-",IF((C8=0),"##",IF(ABS((D8/C8-1)*100)>=500,"##",(D8/C8-1)*100))) -> 20.884521 | F8: 99 | G8: 141 | H8: =IF(F8=G8,"-",IF((F8=0),"##",IF(ABS((G8/F8-1)*100)>=500,"##",(G8/F8-1)*100))) -> 42.424242 | I8: =C8+F8 -> 506 | J8: =D8+G8 -> 633 | K8: =IF(I8=J8,"-",IF((I8=0),"##",IF(ABS((J8/I8-1)*100)>=500,"##",(J8/I8-1)*100))) -> 25.098814
A9: P.E.I. | C9: 282 | D9: 413 | E9: =IF(C9=D9,"-",IF((C9=0),"##",IF(ABS((D9/C9-1)*100)>=500,"##",(D9/C9-1)*100))) -> 46.453901 | F9: 713 | G9: 522 | H9: =IF(F9=G9,"-",IF((F9=0),"##",IF(ABS((G9/F9-1)*100)>=500,"##",(G9/F9-1)*100))) -> -26.788219 | I9: =C9+F9 -> 995 | J9: =D9+G9 -> 935 | K9: =IF(I9=J9,"-",IF((I9=0),"##",IF(ABS((J9/I9-1)*100)>=500,"##",(J9/I9-1)*100))) -> -6.0301508
A10: N.S. | C10: 1575 | D10: 1798 | E10: =IF(C10=D10,"-",IF((C10=0),"##",IF(ABS((D10/C10-1)*100)>=500,"##",(D10/C10-1)*100))) -> 14.15873 | F10: 2803 | G10: 3512 | H10: =IF(F10=G10,"-",IF((F10=0),"##",IF(ABS((G10/F10-1)*100)>=500,"##",(G10/F10-1)*100))) -> 25.294328 | I10: =C10+F10 -> 4378 | J10: =D10+G10 -> 5310 | K10: =IF(I10=J10,"-",IF((I10=0),"##",IF(ABS((J10/I10-1)*100)>=500,"##",(J10/I10-1)*100))) -> 21.288259
A11: N.B. | C11: 772 | D11: 1002 | E11: =IF(C11=D11,"-",IF((C11=0),"##",IF(ABS((D11/C11-1)*100)>=500,"##",(D11/C11-1)*100))) -> 29.792746 | F11: 2390 | G11: 2346 | H11: =IF(F11=G11,"-",IF((F11=0),"##",IF(ABS((G11/F11-1)*100)>=500,"##",(G11/F11-1)*100))) -> -1.8410042 | I11: =C11+F11 -> 3162 | J11: =D11+G11 -> 3348 | K11: =IF(I11=J11,"-",IF((I11=0),"##",IF(ABS((J11/I11-1)*100)>=500,"##",(J11/I11-1)*100))) -> 5.8823529
A12: Atlantic | C12: =SUM(C8:C11) -> 3036 | D12: =SUM(D8:D11) -> 3705 | E12: =IF(C12=D12,"-",IF((C12=0),"##",IF(ABS((D12/C12-1)*100)>=500,"##",(D12/C12-1)*100))) -> 22.035573 | F12: =SUM(F8:F11) -> 6005 | G12: =SUM(G8:G11) -> 6521 | H12: =IF(F12=G12,"-",IF((F12=0),"##",IF(ABS((G12/F12-1)*100)>=500,"##",(G12/F12-1)*100))) -> 8.5928393 | I12: =C12+F12 -> 9041 | J12: =D12+G12 -> 10226 | K12: =IF(I12=J12,"-",IF((I12=0),"##",IF(ABS((J12/I12-1)*100)>=500,"##",(J12/I12-1)*100))) -> 13.106957
A13: Que. | C13: 6866 | D13: 8521 | E13: =IF(C13=D13,"-",IF((C13=0),"##",IF(ABS((D13/C13-1)*100)>=500,"##",(D13/C13-1)*100))) -> 24.104282 | F13: 40366 | G13: 48788 | H13: =IF(F13=G13,"-",IF((F13=0),"##",IF(ABS((G13/F13-1)*100)>=500,"##",(G13/F13-1)*100))) -> 20.864094 | I13: =C13+F13 -> 47232 | J13: =D13+G13 -> 57309 | K13: =IF(I13=J13,"-",IF((I13=0),"##",IF(ABS((J13/I13-1)*100)>=500,"##",(J13/I13-1)*100))) -> 21.335112
A14: Ont. | C14: 20921 | D14: 25755 | E14: =IF(C14=D14,"-",IF((C14=0),"##",IF(ABS((D14/C14-1)*100)>=500,"##",(D14/C14-1)*100))) -> 23.10597 | F14: 57995 | G14: 66529 | H14: =IF(F14=G14,"-",IF((F14=0),"##",IF(ABS((G14/F14-1)*100)>=500,"##",(G14/F14-1)*100))) -> 14.715062 | I14: =C14+F14 -> 78916 | J14: =D14+G14 -> 92284 | K14: =IF(I14=J14,"-",IF((I14=0),"##",IF(ABS((J14/I14-1)*100)>=500,"##",(J14/I14-1)*100))) -> 16.939531
A15: Man. | C15: 1986 | D15: 2647 | E15: =IF(C15=D15,"-",IF((C15=0),"##",IF(ABS((D15/C15-1)*100)>=500,"##",(D15/C15-1)*100))) -> 33.282981 | F15: 4217 | G15: 3953 | H15: =IF(F15=G15,"-",IF((F15=0),"##",IF(ABS((G15/F15-1)*100)>=500,"##",(G15/F15-1)*100))) -> -6.2603747 | I15: =C15+F15 -> 6203 | J15: =D15+G15 -> 6600 | K15: =IF(I15=J15,"-",IF((I15=0),"##",IF(ABS((J15/I15-1)*100)>=500,"##",(J15/I15-1)*100))) -> 6.400129
A16: Sask. | C16: 1143 | D16: 1448 | E16: =IF(C16=D16,"-",IF((C16=0),"##",IF(ABS((D16/C16-1)*100)>=500,"##",(D16/C16-1)*100))) -> 26.684164 | F16: 1660 | G16: 2302 | H16: =IF(F16=G16,"-",IF((F16=0),"##",IF(ABS((G16/F16-1)*100)>=500,"##",(G16/F16-1)*100))) -> 38.674699 | I16: =C16+F16 -> 2803 | J16: =D16+G16 -> 3750 | K16: =IF(I16=J16,"-",IF((I16=0),"##",IF(ABS((J16/I16-1)*100)>=500,"##",(J16/I16-1)*100))) -> 33.78523
A17: Alta. | C17: 8976 | D17: 13323 | E17: =IF(C17=D17,"-",IF((C17=0),"##",IF(ABS((D17/C17-1)*100)>=500,"##",(D17/C17-1)*100))) -> 48.429144 | F17: 14067 | G17: 17289 | H17: =IF(F17=G17,"-",IF((F17=0),"##",IF(ABS((G17/F17-1)*100)>=500,"##",(G17/F17-1)*100))) -> 22.904671 | I17: =C17+F17 -> 23043 | J17: =D17+G17 -> 30612 | K17: =IF(I17=J17,"-",IF((I17=0),"##",IF(ABS((J17/I17-1)*100)>=500,"##",(J17/I17-1)*100))) -> 32.847286
A18: Prairies | C18: =SUM(C15:C17) -> 12105 | D18: =SUM(D15:D17) -> 17418 | E18: =IF(C18=D18,"-",IF((C18=0),"##",IF(ABS((D18/C18-1)*100)>=500,"##",(D18/C18-1)*100))) -> 43.890954 | F18: =SUM(F15:F17) -> 19944 | G18: =SUM(G15:G17) -> 23544 | H18: =IF(F18=G18,"-",IF((F18=0),"##",IF(ABS((G18/F18-1)*100)>=500,"##",(G18/F18-1)*100))) -> 18.050542 | I18: =C18+F18 -> 32049 | J18: =D18+G18 -> 40962 | K18: =IF(I18=J18,"-",IF((I18=0),"##",IF(ABS((J18/I18-1)*100)>=500,"##",(J18/I18-1)*100))) -> 27.81054
A19: B.C. | C19: 6812 | D19: 8088 | E19: =IF(C19=D19,"-",IF((C19=0),"##",IF(ABS((D19/C19-1)*100)>=500,"##",(D19/C19-1)*100))) -> 18.73165 | F19: 28073 | G19: 35272 | H19: =IF(F19=G19,"-",IF((F19=0),"##",IF(ABS((G19/F19-1)*100)>=500,"##",(G19/F19-1)*100))) -> 25.643857 | I19: =C19+F19 -> 34885 | J19: =D19+G19 -> 43360 | K19: =IF(I19=J19,"-",IF((I19=0),"##",IF(ABS((J19/I19-1)*100)>=500,"##",(J19/I19-1)*100))) -> 24.294109
A20: Canada | C20: =SUM(C12:C14,C18:C19) -> 49740 | D20: =SUM(D12:D14,D18:D19) -> 63487 | E20: =IF(C20=D20,"-",IF((C20=0),"##",IF(ABS((D20/C20-1)*100)>=500,"##",(D20/C20-1)*100))) -> 27.637716 | F20: =SUM(F12:F14,F18:F19) -> 152383 | G20: =SUM(G12:G14,G18:G19) -> 180654 | H20: =IF(F20=G20,"-",IF((F20=0),"##",IF(ABS((G20/F20-1)*100)>=500,"##",(G20/F20-1)*100))) -> 18.552594 | I20: =C20+F20 -> 202123 | J20: =D20+G20 -> 244141 | K20: =IF(I20=J20,"-",IF((I20=0),"##",IF(ABS((J20/I20-1)*100)>=500,"##",(J20/I20-1)*100))) -> 20.788332
A21: Metropolitan Areas
A23: Abbotsford-Mission | C23: 333 | D23: 325 | E23: =IF(C23=D23,"-",IF((C23=0),"##",IF(ABS((D23/C23-1)*100)>=500,"##",(D23/C23-1)*100))) -> -2.4024024 | F23: 777 | G23: 753 | H23: =IF(F23=G23,"-",IF((F23=0),"##",IF(ABS((G23/F23-1)*100)>=500,"##",(G23/F23-1)*100))) -> -3.0888031 | I23: =C23+F23 -> 1110 | J23: =D23+G23 -> 1078 | K23: =IF(I23=J23,"-",IF((I23=0),"##",IF(ABS((J23/I23-1)*100)>=500,"##",(J23/I23-1)*100))) -> -2.8828829
A24: Barrie | C24: 609 | D24: 798 | E24: =IF(C24=D24,"-",IF((C24=0),"##",IF(ABS((D24/C24-1)*100)>=500,"##",(D24/C24-1)*100))) -> 31.034483 | F24: 556 | G24: 1427 | H24: =IF(F24=G24,"-",IF((F24=0),"##",IF(ABS((G24/F24-1)*100)>=500,"##",(G24/F24-1)*100))) -> 156.65468 | I24: =C24+F24 -> 1165 | J24: =D24+G24 -> 2225 | K24: =IF(I24=J24,"-",IF((I24=0),"##",IF(ABS((J24/I24-1)*100)>=500,"##",(J24/I24-1)*100))) -> 90.987124
A25: Belleville | C25: 423 | D25: 383 | E25: =IF(C25=D25,"-",IF((C25=0),"##",IF(ABS((D25/C25-1)*100)>=500,"##",(D25/C25-1)*100))) -> -9.4562648 | F25: 250 | G25: 141 | H25: =IF(F25=G25,"-",IF((F25=0),"##",IF(ABS((G25/F25-1)*100)>=500,"##",(G25/F25-1)*100))) -> -43.6 | I25: =C25+F25 -> 673 | J25: =D25+G25 -> 524 | K25: =IF(I25=J25,"-",IF((I25=0),"##",IF(ABS((J25/I25-1)*100)>=500,"##",(J25/I25-1)*100))) -> -22.139673
A26: Brantford | C26: 660 | D26: 580 | E26: =IF(C26=D26,"-",IF((C26=0),"##",IF(ABS((D26/C26-1)*100)>=500,"##",(D26/C26-1)*100))) -> -12.121212 | F26: 528 | G26: 727 | H26: =IF(F26=G26,"-",IF((F26=0),"##",IF(ABS((G26/F26-1)*100)>=500,"##",(G26/F26-1)*100))) -> 37.689394 | I26: =C26+F26 -> 1188 | J26: =D26+G26 -> 1307 | K26: =IF(I26=J26,"-",IF((I26=0),"##",IF(ABS((J26/I26-1)*100)>=500,"##",(J26/I26-1)*100))) -> 10.016835
A27: Calgary | C27: 3487 | D27: 5512 | E27: =IF(C27=D27,"-",IF((C27=0),"##",IF(ABS((D27/C27-1)*100)>=500,"##",(D27/C27-1)*100))) -> 58.072842 | F27: 5748 | G27: 9505 | H27: =IF(F27=G27,"-",IF((F27=0),"##",IF(ABS((G27/F27-1)*100)>=500,"##",(G27/F27-1)*100))) -> 65.361865 | I27: =C27+F27 -> 9235 | J27: =D27+G27 -> 15017 | K27: =IF(I27=J27,"-",IF((I27=0),"##",IF(ABS((J27/I27-1)*100)>=500,"##",(J27/I27-1)*100))) -> 62.609637
A28: Edmonton | C28: 4138 | D28: 5701 | E28: =IF(C28=D28,"-",IF((C28=0),"##",IF(ABS((D28/C28-1)*100)>=500,"##",(D28/C28-1)*100))) -> 37.77187 | F28: 7374 | G28: 6845 | H28: =IF(F28=G28,"-",IF((F28=0),"##",IF(ABS((G28/F28-1)*100)>=500,"##",(G28/F28-1)*100))) -> -7.1738541 | I28: =C28+F28 -> 11512 | J28: =D28+G28 -> 12546 | K28: =IF(I28=J28,"-",IF((I28=0),"##",IF(ABS((J28/I28-1)*100)>=500,"##",(J28/I28-1)*100))) -> 8.9819319
A29: Greater/Grand Sudbury | C29: 116 | D29: 190 | E29: =IF(C29=D29,"-",IF((C29=0),"##",IF(ABS((D29/C29-1)*100)>=500,"##",(D29/C29-1)*100))) -> 63.793103 | F29: 102 | G29: 244 | H29: =IF(F29=G29,"-",IF((F29=0),"##",IF(ABS((G29/F29-1)*100)>=500,"##",(G29/F29-1)*100))) -> 139.21569 | I29: =C29+F29 -> 218 | J29: =D29+G29 -> 434 | K29: =IF(I29=J29,"-",IF((I29=0),"##",IF(ABS((J29/I29-1)*100)>=500,"##",(J29/I29-1)*100))) -> 99.082569
A30: Guelph | C30: 209 | D30: 192 | E30: =IF(C30=D30,"-",IF((C30=0),"##",IF(ABS((D30/C30-1)*100)>=500,"##",(D30/C30-1)*100))) -> -8.1339713 | F30: 375 | G30: 574 | H30: =IF(F30=G30,"-",IF((F30=0),"##",IF(ABS((G30/F30-1)*100)>=500,"##",(G30/F30-1)*100))) -> 53.066667 | I30: =C30+F30 -> 584 | J30: =D30+G30 -> 766 | K30: =IF(I30=J30,"-",IF((I30=0),"##",IF(ABS((J30/I30-1)*100)>=500,"##",(J30/I30-1)*100))) -> 31.164384
A31: Halifax | C31: 1019 | D31: 935 | E31: =IF(C31=D31,"-",IF((C31=0),"##",IF(ABS((D31/C31-1)*100)>=500,"##",(D31/C31-1)*100))) -> -8.2433759 | F31: 2230 | G31: 2859 | H31: =IF(F31=G31,"-",IF((F31=0),"##",IF(ABS((G31/F31-1)*100)>=500,"##",(G31/F31-1)*100))) -> 28.206278 | I31: =C31+F31 -> 3249 | J31: =D31+G31 -> 3794 | K31: =IF(I31=J31,"-",IF((I31=0),"##",IF(ABS((J31/I31-1)*100)>=500,"##",(J31/I31-1)*100))) -> 16.774392
A32: Hamilton | C32: 529 | D32: 738 | E32: =IF(C32=D32,"-",IF((C32=0),"##",IF(ABS((D32/C32-1)*100)>=500,"##",(D32/C32-1)*100))) -> 39.508507 | F32: 2902 | G32: 3449 | H32: =IF(F32=G32,"-",IF((F32=0),"##",IF(ABS((G32/F32-1)*100)>=500,"##",(G32/F32-1)*100))) -> 18.84907 | I32: =C32+F32 -> 3431 | J32: =D32+G32 -> 4187 | K32: =IF(I32=J32,"-",IF((I32=0),"##",IF(ABS((J32/I32-1)*100)>=500,"##",(J32/I32-1)*100))) -> 22.034392
A33: Kelowna | C33: 383 | D33: 926 | E33: =IF(C33=D33,"-",IF((C33=0),"##",IF(ABS((D33/C33-1)*100)>=500,"##",(D33/C33-1)*100))) -> 141.77546 | F33: 1411 | G33: 2340 | H33: =IF(F33=G33,"-",IF((F33=0),"##",IF(ABS((G33/F33-1)*100)>=500,"##",(G33/F33-1)*100))) -> 65.83983 | I33: =C33+F33 -> 1794 | J33: =D33+G33 -> 3266 | K33: =IF(I33=J33,"-",IF((I33=0),"##",IF(ABS((J33/I33-1)*100)>=500,"##",(J33/I33-1)*100))) -> 82.051282
A34: Kingston | C34: 305 | D34: 396 | E34: =IF(C34=D34,"-",IF((C34=0),"##",IF(ABS((D34/C34-1)*100)>=500,"##",(D34/C34-1)*100))) -> 29.836066 | F34: 736 | G34: 975 | H34: =IF(F34=G34,"-",IF((F34=0),"##",IF(ABS((G34/F34-1)*100)>=500,"##",(G34/F34-1)*100))) -> 32.472826 | I34: =C34+F34 -> 1041 | J34: =D34+G34 -> 1371 | K34: =IF(I34=J34,"-",IF((I34=0),"##",IF(ABS((J34/I34-1)*100)>=500,"##",(J34/I34-1)*100))) -> 31.700288
... A40: Oshawa | C40: 793 | D40: 1407 | E40: =IF(C40=D40,"-",IF((C40=0),"##",IF(ABS((D40/C40-1)*100)>=500,"##",(D40/C40-1)*100))) -> 77.427491 | F40: 1873 | G40: 2456 | H40: =IF(F40=G40,"-",IF((F40=0),"##",IF(ABS((G40/F40-1)*100)>=500,"##",(G40/F40-1)*100))) -> 31.126535 | I40: =C40+F40 -> 2666 | J40: =D40+G40 -> 3863 | K40: =IF(I40=J40,"-",IF((I40=0),"##",IF(ABS((J40/I40-1)*100)>=500,"##",(J40/I40-1)*100))) -> 44.898725
A41: Ottawa-Gatineau | C41: =+SUM(C42+C43) -> 3411 | D41: =+SUM(D42+D43) -> 4003 | E41: =IF(C41=D41,"-",IF((C41=0),"##",IF(ABS((D41/C41-1)*100)>=500,"##",(D41/C41-1)*100))) -> 17.355614 | F41: =+SUM(F42+F43) -> 9623 | G41: =+SUM(G42+G43) -> 9277 | H41: =IF(F41=G41,"-",IF((F41=0),"##",IF(ABS((G41/F41-1)*100)>=500,"##",(G41/F41-1)*100))) -> -3.5955523 | I41: =C41+F41 -> 13034 | J41: =D41+G41 -> 13280 | K41: =IF(I41=J41,"-",IF((I41=0),"##",IF(ABS((J41/I41-1)*100)>=500,"##",(J41/I41-1)*100))) -> 1.8873715
A42: Gatineau | C42: 544 | D42: 727 | E42: =IF(C42=D42,"-",IF((C42=0),"##",IF(ABS((D42/C42-1)*100)>=500,"##",(D42/C42-1)*100))) -> 33.639706 | F42: 2540 | G42: 2332 | H42: =IF(F42=G42,"-",IF((F42=0),"##",IF(ABS((G42/F42-1)*100)>=500,"##",(G42/F42-1)*100))) -> -8.1889764 | I42: =C42+F42 -> 3084 | J42: =D42+G42 -> 3059 | K42: =IF(I42=J42,"-",IF((I42=0),"##",IF(ABS((J42/I42-1)*100)>=500,"##",(J42/I42-1)*100))) -> -0.81063554
A43: Ottawa | C43: 2867 | D43: 3276 | E43: =IF(C43=D43,"-",IF((C43=0),"##",IF(ABS((D43/C43-1)*100)>=500,"##",(D43/C43-1)*100))) -> 14.265783 | F43: 7083 | G43: 6945 | H43: =IF(F43=G43,"-",IF((F43=0),"##",IF(ABS((G43/F43-1)*100)>=500,"##",(G43/F43-1)*100))) -> -1.948327 | I43: =C43+F43 -> 9950 | J43: =D43+G43 -> 10221 | K43: =IF(I43=J43,"-",IF((I43=0),"##",IF(ABS((J43/I43-1)*100)>=500,"##",(J43/I43-1)*100))) -> 2.7236181
A44: Peterborough | C44: 264 | D44: 335 | E44: =IF(C44=D44,"-",IF((C44=0),"##",IF(ABS((D44/C44-1)*100)>=500,"##",(D44/C44-1)*100))) -> 26.893939 | F44: 264 | G44: 289 | H44: =IF(F44=G44,"-",IF((F44=0),"##",IF(ABS((G44/F44-1)*100)>=500,"##",(G44/F44-1)*100))) -> 9.469697 | I44: =C44+F44 -> 528 | J44: =D44+G44 -> 624 | K44: =IF(I44=J44,"-",IF((I44=0),"##",IF(ABS((J44/I44-1)*100)>=500,"##",(J44/I44-1)*100))) -> 18.181818
A45: Québec | C45: 864 | D45: 1123 | E45: =IF(C45=D45,"-",IF((C45=0),"##",IF(ABS((D45/C45-1)*100)>=500,"##",(D45/C45-1)*100))) -> 29.976852 | F45: 5849 | G45: 8266 | H45: =IF(F45=G45,"-",IF((F45=0),"##",IF(ABS((G45/F45-1)*100)>=500,"##",(G45/F45-1)*100))) -> 41.323303 | I45: =C45+F45 -> 6713 | J45: =D45+G45 -> 9389 | K45: =IF(I45=J45,"-",IF((I45=0),"##",IF(ABS((J45/I45-1)*100)>=500,"##",(J45/I45-1)*100))) -> 39.862952
A46: Regina | C46: 288 | D46: 405 | E46: =IF(C46=D46,"-",IF((C46=0),"##",IF(ABS((D46/C46-1)*100)>=500,"##",(D46/C46-1)*100))) -> 40.625 | F46: 478 | G46: 578 | H46: =IF(F46=G46,"-",IF((F46=0),"##",IF(ABS((G46/F46-1)*100)>=500,"##",(G46/F46-1)*100))) -> 20.920502 | I46: =C46+F46 -> 766 | J46: =D46+G46 -> 983 | K46: =IF(I46=J46,"-",IF((I46=0),"##",IF(ABS((J46/I46-1)*100)>=500,"##",(J46/I46-1)*100))) -> 28.328982
A47: Saguenay | C47: 200 | D47: 314 | E47: =IF(C47=D47,"-",IF((C47=0),"##",IF(ABS((D47/C47-1)*100)>=500,"##",(D47/C47-1)*100))) -> 57 | F47: 335 | G47: 279 | H47: =IF(F47=G47,"-",IF((F47=0),"##",IF(ABS((G47/F47-1)*100)>=500,"##",(G47/F47-1)*100))) -> -16.716418 | I47: =C47+F47 -> 535 | J47: =D47+G47 -> 593 | K47: =IF(I47=J47,"-",IF((I47=0),"##",IF(ABS((J47/I47-1)*100)>=500,"##",(J47/I47-1)*100))) -> 10.841121
...

Sheet Table 3
A1: Table 3
A2: Dwelling Starts in Urban Centres and Canada, Seasonally Adjusted at Annual Rates
E5: Centres 10,000 Population and Over1
A7: Period | D7: Single- | E7: All | F7: Total | G7: Other | H7: Canada
D8: Detached | E8: Others | G8: Areas
A11: 2019 2 | D11: 46941 | E11: 149788 | F11: =SUM(D11:E11) -> 196729 | G11: 11956 | H11: 208685
A12: 20202 | D12: 49740 | E12: 152383 | F12: =SUM(D12:E12) -> 202123 | G12: 15679 | H12: 217802
A13: 2020 | B13: 1st Q. | D13: 49710 | E13: 136053 | F13: 185763 | G13: 11675 | H13: =IF(SUM(F13,G13)=0,"",SUM(F13,G13)) -> 197438
B14: 2nd Q. | D14: 41706 | E14: 136738 | F14: 178444 | G14: 13968 | H14: =IF(SUM(F14,G14)=0,"",SUM(F14,G14)) -> 192412
B15: 3rd Q. | D15: 50449 | E15: 175711 | F15: 226160 | G15: 14213 | H15: =IF(SUM(F15,G15)=0,"",SUM(F15,G15)) -> 240373
B16: 4th Q. | D16: 57455 | E16: 162475 | F16: 219930 | G16: 23125 | H16: =IF(SUM(F16,G16)=0,"",SUM(F16,G16)) -> 243055
A18: 2021 | B18: 1st Q. | D18: 73117 | E18: 190714 | F18: 263831 | G18: 24986 | H18: =IF(SUM(F18,G18)=0,"",SUM(F18,G18)) -> 288817
B19: 2nd Q. | D19: 66183 | E19: 181952 | F19: 248135 | G19: 29736 | H19: =IF(SUM(F19,G19)=0,"",SUM(F19,G19)) -> 277871
B20: 3rd Q. | D20: 60837 | E20: 174634 | F20: 235471 | G20: 27699 | H20: =IF(SUM(F20,G20)=0,"",SUM(F20,G20)) -> 263170
B21: 4th Q. | D21: 58189 | E21: 179514 | F21: 237703 | G21: 26224 | H21: =IF(SUM(F21,G21)=0,"",SUM(F21,G21)) -> 263927
A22: =A13 -> 2020 | B22: January | D22: 47171 | E22: 148851 | F22: 196022 | G22: 14988 | H22: =IF(SUM(F22,G22)=0,"",SUM(F22,G22)) -> 211010
B23: February | D23: 51364 | E23: 141761 | F23: 193125 | G23: 14663 | H23: =IF(SUM(F23,G23)=0,"",SUM(F23,G23)) -> 207788
B24: March | D24: 55399 | E24: 123854 | F24: 179253 | G24: 13964 | H24: =IF(SUM(F24,G24)=0,"",SUM(F24,G24)) -> 193217
B25: April | D25: 35937 | E25: 119977 | F25: 155914 | G25: 7117 | H25: =IF(SUM(F25,G25)=0,"",SUM(F25,G25)) -> 163031
B26: May | D26: 45476 | E26: 136569 | F26: 182045 | G26: 13384 | H26: =IF(SUM(F26,G26)=0,"",SUM(F26,G26)) -> 195429
B27: June | D27: 43802 | E27: 153679 | F27: 197481 | G27: 13709 | H27: =IF(SUM(F27,G27)=0,"",SUM(F27,G27)) -> 211190
B28: July | D28: 49804 | E28: 180917 | F28: 230721 | G28: 14346 | H28: =IF(SUM(F28,G28)=0,"",SUM(F28,G28)) -> 245067
B29: August | D29: 48253 | E29: 200662 | F29: 248915 | G29: 14178 | H29: =IF(SUM(F29,G29)=0,"",SUM(F29,G29)) -> 263093
B30: September | D30: 51920 | E30: 146036 | F30: 197956 | G30: 14695 | H30: =IF(SUM(F30,G30)=0,"",SUM(F30,G30)) -> 212651
B31: October | D31: 59332 | E31: 148480 | F31: 207812 | G31: 19969 | H31: =IF(SUM(F31,G31)=0,"",SUM(F31,G31)) -> 227781
B32: November | D32: 57118 | E32: 179454 | F32: 236572 | G32: 21220 | H32: =IF(SUM(F32,G32)=0,"",SUM(F32,G32)) -> 257792
B33: December | D33: 52367 | E33: 159291 | F33: 211658 | G33: 21375 | H33: =IF(SUM(F33,G33)=0,"",SUM(F33,G33)) -> 233033
A35: =A18 -> 2021 | B35: January | D35: 77436 | E35: 201480 | F35: 278916 | G35: 36588 | H35: =IF(SUM(F35,G35)=0,"",SUM(F35,G35)) -> 315504
B36: February | D36: 73398 | E36: 161282 | F36: 234680 | G36: 32304 | H36: =IF(SUM(F36,G36)=0,"",SUM(F36,G36)) -> 266984
B37: March | D37: 77009 | E37: 219748 | F37: 296757 | G37: 33358 | H37: =IF(SUM(F37,G37)=0,"",SUM(F37,G37)) -> 330115
B38: April | D38: 78763 | E38: 169989 | F38: 248752 | G38: 27272 | H38: =IF(SUM(F38,G38)=0,"",SUM(F38,G38)) -> 276024
B39: May | D39: 65835 | E39: 188484 | F39: 254319 | G39: 29641 | H39: =IF(SUM(F39,G39)=0,"",SUM(F39,G39)) -> 283960
B40: June | D40: 59997 | E40: 189264 | F40: 249261 | G40: 29079 | H40: =IF(SUM(F40,G40)=0,"",SUM(F40,G40)) -> 278340
B41: July | D41: 62405 | E41: 182300 | F41: 244705 | G41: 29362 | H41: =IF(SUM(F41,G41)=0,"",SUM(F41,G41)) -> 274067
B42: August | D42: 60097 | E42: 172201 | F42: 232298 | G42: 28667 | H42: =IF(SUM(F42,G42)=0,"",SUM(F42,G42)) -> 260965
B43: September | D43: 57400 | E43: 165285 | F43: 222685 | G43: 28353 | H43: =IF(SUM(F43,G43)=0,"",SUM(F43,G43)) -> 251038
B44: October | D44: 57953 | E44: 156454 | F44: 214407 | G44: 23005 | H44: =IF(SUM(F44,G44)=0,"",SUM(F44,G44)) -> 237412
B45: November | D45: 57648 | E45: 222150 | F45: 279798 | G45: 24015 | H45: =IF(SUM(F45,G45)=0,"",SUM(F45,G45)) -> 303813
B46: December | D46: 55231 | E46: 157687 | F46: 212918 | G46: 23188 | H46: =IF(SUM(F46,G46)=0,"",SUM(F46,G46)) -> 236106
A47: =Titles!$A$12 -> 1 Data for 2020 and 2021 based on 2016 Census Definitions.
...

Sheet Table 4
A1: Table 4
A2: Dwelling Starts in Urban Centres1, by Region, Seasonally Adjusted at Annual Rates
A6: Period | E6: Atlantic | F6: Québec | G6: Ontario | H6: Prairies | I6: B. C. | J6: Total
A7: 2019 2 | E7: 8168 | F7: 43534 | G7: 67864 | H7: 33948 | I7: 43215 | J7: 196729
A8: 2020 2 | E8: 9041 | F8: 47232 | G8: 78916 | H8: 32049 | I8: 34885 | J8: 202123
A10: Single-Detached | B10: 2020 | C10: 3rd Q | E10: 3040 | F10: 7281 | G10: 21898 | H10: 11186 | I10: 7044 | J10: =SUM(E10:I10) -> 50449
B11: 2020 | C11: 4th Q | E11: 3334 | F11: 8206 | G11: 24746 | H11: 14185 | I11: 6984 | J11: =SUM(E11:I11) -> 57455
A12: All Others | B12: 2020 | C12: 3rd Q | E12: 7647 | F12: 45645 | G12: 71383 | H12: 20236 | I12: 30800 | J12: =SUM(E12:I12) -> 175711
B13: 2020 | C13: 4th Q | E13: 7030 | F13: 43276 | G13: 54740 | H13: 26516 | I13: 30913 | J13: =SUM(E13:I13) -> 162475
A14: Total | B14: 2020 | C14: 3rd Q | E14: =SUM(E10,E12) -> 10687 | F14: =SUM(F10,F12) -> 52926 | G14: =SUM(G10,G12) -> 93281 | H14: =SUM(H10,H12) -> 31422 | I14: =SUM(I10,I12) -> 37844 | J14: =SUM(E14:I14) -> 226160
B15: 2020 | C15: 4th Q | E15: =SUM(E11,E13) -> 10364 | F15: =SUM(F11,F13) -> 51482 | G15: =SUM(G11,G13) -> 79486 | H15: =SUM(H11,H13) -> 40701 | I15: =SUM(I11,I13) -> 37897 | J15: =SUM(E15:I15) -> 219930
A17: Single-Detached | B17: 2021 | C17: 3rd Q | E17: 3561 | F17: 7415 | G17: 24857 | H17: 17414 | I17: 7590 | J17: =SUM(E17:I17) -> 60837
B18: 2021 | C18: 4th Q | E18: 3855 | F18: 6529 | G18: 23730 | H18: 16573 | I18: 7502 | J18: =SUM(E18:I18) -> 58189
A19: All Others | B19: 2021 | C19: 3rd Q | E19: 4270 | F19: 45782 | G19: 69193 | H19: 22067 | I19: 33322 | J19: =SUM(E19:I19) -> 174634
B20: 2021 | C20: 4th Q | E20: 9503 | F20: 43743 | G20: 67434 | H20: 27176 | I20: 31658 | J20: =SUM(E20:I20) -> 179514
A21: Total | B21: 2021 | C21: 3rd Q | E21: =SUM(E17,E19) -> 7831 | F21: =SUM(F17,F19) -> 53197 | G21: =SUM(G17,G19) -> 94050 | H21: =SUM(H17,H19) -> 39481 | I21: =SUM(I17,I19) -> 40912 | J21: =SUM(E21:I21) -> 235471
B22: 2021 | C22: 4th Q | E22: =SUM(E18,E20) -> 13358 | F22: =SUM(F18,F20) -> 50272 | G22: =SUM(G18,G20) -> 91164 | H22: =SUM(H18,H20) -> 43749 | I22: =SUM(I18,I20) -> 39160 | J22: =SUM(E22:I22) -> 237703
A24: Single-Detached | B24: 2020 | C24: Oct. | E24: 3126 | F24: 8774 | G24: 26472 | H24: 13779 | I24: 7181 | J24: =SUM(E24:I24) -> 59332
B25: 2020 | C25: Nov. | E25: 3674 | F25: 7932 | G25: 24154 | H25: 13795 | I25: 7563 | J25: =SUM(E25:I25) -> 57118
B26: 2020 | C26: Dec. | E26: 3228 | F26: 7624 | G26: 19981 | H26: 14631 | I26: 6903 | J26: =SUM(E26:I26) -> 52367
A27: All Others | B27: 2020 | C27: Oct. | E27: 2259 | F27: 37623 | G27: 56555 | H27: 29545 | I27: 22498 | J27: =SUM(E27:I27) -> 148480
B28: 2020 | C28: Nov. | E28: 10405 | F28: 46975 | G28: 57206 | H28: 26167 | I28: 38701 | J28: =SUM(E28:I28) -> 179454
B29: 2020 | C29: Dec. | E29: 9655 | F29: 44265 | G29: 48923 | H29: 23883 | I29: 32565 | J29: =SUM(E29:I29) -> 159291
A30: Total | B30: 2020 | C30: Oct. | E30: =SUM(E24,E27) -> 5385 | F30: =SUM(F24,F27) -> 46397 | G30: =SUM(G24,G27) -> 83027 | H30: =SUM(H24,H27) -> 43324 | I30: =SUM(I24,I27) -> 29679 | J30: =SUM(J24,J27) -> 207812
B31: 2020 | C31: Nov. | E31: =SUM(E25,E28) -> 14079 | F31: =SUM(F25,F28) -> 54907 | G31: =SUM(G25,G28) -> 81360 | H31: =SUM(H25,H28) -> 39962 | I31: =SUM(I25,I28) -> 46264 | J31: =SUM(J25,J28) -> 236572
B32: 2020 | C32: Dec. | E32: =SUM(E26,E29) -> 12883 | F32: =SUM(F26,F29) -> 51889 | G32: =SUM(G26,G29) -> 68904 | H32: =SUM(H26,H29) -> 38514 | I32: =SUM(I26,I29) -> 39468 | J32: =SUM(J26,J29) -> 211658
A34: Single-Detached | B34: 2021 | C34: Oct. | E34: 5380 | F34: 6989 | G34: 21613 | H34: 16556 | I34: 7415 | J34: =SUM(E34:I34) -> 57953
B35: 2021 | C35: Nov. | E35: 2878 | F35: 7466 | G35: 24291 | H35: 15761 | I35: 7252 | J35: =SUM(E35:I35) -> 57648
B36: 2021 | C36: Dec. | E36: 3199 | F36: 4523 | G36: 22076 | H36: 16696 | I36: 8737 | J36: =SUM(E36:I36) -> 55231
A37: All Others | B37: 2021 | C37: Oct. | E37: 8500 | F37: 42618 | G37: 55138 | H37: 25247 | I37: 24951 | J37: =SUM(E37:I37) -> 156454
B38: 2021 | C38: Nov. | E38: 9940 | F38: 48789 | G38: 101089 | H38: 33769 | I38: 28563 | J38: =SUM(E38:I38) -> 222150
B39: 2021 | C39: Dec. | E39: 10998 | F39: 37470 | G39: 44211 | H39: 22754 | I39: 42254 | J39: =SUM(E39:I39) -> 157687
A40: Total | B40: 2021 | C40: Oct. | E40: =SUM(E34,E37) -> 13880 | F40: =SUM(F34,F37) -> 49607 | G40: =SUM(G34,G37) -> 76751 | H40: =SUM(H34,H37) -> 41803 | I40: =SUM(I34,I37) -> 32366 | J40: =SUM(J34,J37) -> 214407
B41: 2021 | C41: Nov. | E41: =SUM(E35,E38) -> 12818 | F41: =SUM(F35,F38) -> 56255 | G41: =SUM(G35,G38) -> 125380 | H41: =SUM(H35,H38) -> 49530 | I41: =SUM(I35,I38) -> 35815 | J41: =SUM(J35,J38) -> 279798
B42: 2021 | C42: Dec. | E42: =SUM(E36,E39) -> 14197 | F42: =SUM(F36,F39) -> 41993 | G42: =SUM(G36,G39) -> 66287 | H42: =SUM(H36,H39) -> 39450 | I42: =SUM(I36,I39) -> 50991 | J42: =SUM(J36,J39) -> 212918
A43: =Titles!$A$12 -> 1 Data for 2020 and 2021 based on 2016 Census Definitions.
A44: 2 Data are Actual Dwelling Starts.
A45: =Titles!$A$10 -> Source: CMHC Starts and Completion Survey, Market Absorption Survey

Sheet Table 5
A1: Table 5
A2: Dwelling Starts in Urban Centres1, by Region, Seasonally Adjusted at Annual Rates
A6: Period | D6: Atlantic | E6: Québec | F6: Ontario | G6: Prairies | H6: B. C. | I6: Total
A7: 2019 2 | D7: 8168 | E7: 43534 | F7: 67864 | G7: 33948 | H7: 43215 | I7: 196729
A8: 2020 2 | D8: 9041 | E8: 47232 | F8: 78916 | G8: 32049 | H8: 34885 | I8: 202123
A9: 2019 | B9: 1st Q. | D9: 5638 | E9: 41293 | F9: 58071 | G9: 26953 | H9: 39951 | I9: 171906
B10: 2nd Q. | D10: 9317 | E10: 48236 | F10: 67433 | G10: 34298 | H10: 48737 | I10: 208021
B11: 3rd Q. | D11: 9121 | E11: 42885 | F11: 78452 | G11: 37882 | H11: 42120 | I11: 210460
B12: 4th Q. | D12: 7873 | E12: 41344 | F12: 65714 | G12: 36252 | H12: 40172 | I12: 191355
A13: 2020 | B13: 1st Q. | D13: 8653 | E13: 46067 | F13: 66430 | G13: 31167 | H13: 33446 | I13: 185763
B14: 2nd Q. | D14: 6641 | E14: 39413 | F14: 75823 | G14: 25864 | H14: 30703 | I14: 178444
B15: 3rd Q. | D15: 10687 | E15: 52926 | F15: 93281 | G15: 31422 | H15: 37844 | I15: 226160
B16: 4th Q. | D16: 10364 | E16: 51482 | F16: 79486 | G16: 40701 | H16: 37897 | I16: 219930
A17: 2021 | B17: 1st Q. | D17: 10864 | E17: 71262 | F17: 93989 | G17: 37905 | H17: 49811 | I17: 263831
B18: 2nd Q. | D18: 10033 | E18: 59954 | F18: 91046 | G18: 42674 | H18: 44428 | I18: 248135
B19: 3rd Q. | D19: 7831 | E19: 53197 | F19: 94050 | G19: 39481 | H19: 40912 | I19: 235471
B20: 4th Q. | D20: 13358 | E20: 50272 | F20: 91164 | G20: 43749 | H20: 39160 | I20: 237703
A21: =A9 -> 2019 | B21: January | D21: 5334 | E21: 38386 | F21: 72219 | G21: 30763 | H21: 40487 | I21: =IF(SUM(D21:H21)=0,"",SUM(D21:H21)) -> 187189
B22: February | D22: 4339 | E22: 32627 | F22: 52771 | G22: 24371 | H22: 35747 | I22: =IF(SUM(D22:H22)=0,"",SUM(D22:H22)) -> 149855
B23: March | D23: 5849 | E23: 59992 | F23: 57521 | G23: 23769 | H23: 31920 | I23: =IF(SUM(D23:H23)=0,"",SUM(D23:H23)) -> 179051
B24: April | D24: 5526 | E24: 46451 | F24: 85054 | G24: 31461 | H24: 50873 | I24: =IF(SUM(D24:H24)=0,"",SUM(D24:H24)) -> 219365
B25: May | D25: 6540 | E25: 44811 | F25: 49718 | G25: 31589 | H25: 53862 | I25: =IF(SUM(D25:H25)=0,"",SUM(D25:H25)) -> 186520
B26: June | D26: 14598 | E26: 48301 | F26: 66102 | G26: 42431 | H26: 59890 | I26: =IF(SUM(D26:H26)=0,"",SUM(D26:H26)) -> 231322
B27: July | D27: 8208 | E27: 44812 | F27: 68233 | G27: 35685 | H27: 49044 | I27: =IF(SUM(D27:H27)=0,"",SUM(D27:H27)) -> 205982
B28: August | D28: 9549 | E28: 46814 | F28: 82144 | G28: 37868 | H28: 34992 | I28: =IF(SUM(D28:H28)=0,"",SUM(D28:H28)) -> 211367
B29: September | D29: 9756 | E29: 37167 | F29: 84495 | G29: 39593 | H29: 39819 | I29: =IF(SUM(D29:H29)=0,"",SUM(D29:H29)) -> 210830
B30: October | D30: 6122 | E30: 49514 | F30: 73830 | G30: 31914 | H30: 33115 | I30: =IF(SUM(D30:H30)=0,"",SUM(D30:H30)) -> 194495
B31: November | D31: 9093 | E31: 39602 | F31: 62981 | G31: 32291 | H31: 46998 | I31: =IF(SUM(D31:H31)=0,"",SUM(D31:H31)) -> 190965
B32: December | D32: 9072 | E32: 35810 | F32: 57353 | G32: 44117 | H32: 41655 | I32: =IF(SUM(D32:H32)=0,"",SUM(D32:H32)) -> 188007
A33: =A13 -> 2020 | B33: January | D33: 5118 | E33: 69255 | F33: 67805 | G33: 29309 | H33: 24535 | I33: =IF(SUM(D33:H33)=0,"",SUM(D33:H33)) -> 196022
B34: February | D34: 10556 | E34: 43785 | F34: 76258 | G34: 24681 | H34: 37845 | I34: =IF(SUM(D34:H34)=0,"",SUM(D34:H34)) -> 193125
B35: March | D35: 5632 | E35: 42185 | F35: 63860 | G35: 37784 | H35: 29792 | I35: =IF(SUM(D35:H35)=0,"",SUM(D35:H35)) -> 179253
B36: April | D36: 5072 | E36: 0 | F36: 91832 | G36: 31535 | H36: 27475 | I36: =IF(SUM(D36:H36)=0,"",SUM(D36:H36)) -> 155914
B37: May | D37: 7823 | E37: 57697 | F37: 56376 | G37: 23914 | H37: 36235 | I37: =IF(SUM(D37:H37)=0,"",SUM(D37:H37)) -> 182045
B38: June | D38: 6981 | E38: 52941 | F38: 77386 | G38: 24059 | H38: 36114 | I38: =IF(SUM(D38:H38)=0,"",SUM(D38:H38)) -> 197481
B39: July | D39: 15222 | E39: 55677 | F39: 84455 | G39: 36626 | H39: 38741 | I39: =IF(SUM(D39:H39)=0,"",SUM(D39:H39)) -> 230721
B40: August | D40: 10011 | E40: 56030 | F40: 114477 | G40: 26601 | H40: 41796 | I40: =IF(SUM(D40:H40)=0,"",SUM(D40:H40)) -> 248915
B41: September | D41: 9056 | E41: 47741 | F41: 80075 | G41: 30376 | H41: 30708 | I41: =IF(SUM(D41:H41)=0,"",SUM(D41:H41)) -> 197956
B42: October | D42: 5385 | E42: 46397 | F42: 83027 | G42: 43324 | H42: 29679 | I42: =IF(SUM(D42:H42)=0,"",SUM(D42:H42)) -> 207812
B43: November | D43: 14079 | E43: 54907 | F43: 81360 | G43: 39962 | H43: 46264 | I43: =IF(SUM(D43:H43)=0,"",SUM(D43:H43)) -> 236572
...

Sheet Table 6
A1: Table 6
A2: Dwelling Starts in Urban Centres1, Atlantic Provinces, Seasonally Adjusted at Annual Rates
A5: Period | D5: Newfoundland | E5: Prince Edward | F5: Nova Scotia | G5: New Brunswick | H5: Total
E6: Island
A9: 2019 2 | D9: 639 | E9: 1114 | F9: 4080 | G9: 2335 | H9: 8168
A10: 2020 2 | D10: 506 | E10: 995 | F10: 4378 | G10: 3162 | H10: 9041
A11: 2019 | B11: 1st Q. | D11: 462 | E11: 390 | F11: 3596 | G11: 1190 | H11: 5638
B12: 2nd Q. | D12: 575 | E12: 845 | F12: 4714 | G12: 3183 | H12: 9317
B13: 3rd Q. | D13: 688 | E13: 1958 | F13: 3756 | G13: 2719 | H13: 9121
B14: 4th Q. | D14: 734 | E14: 1115 | F14: 4035 | G14: 1989 | H14: 7873
A15: 2020 | B15: 1st Q. | D15: 494 | E15: 645 | F15: 4023 | G15: 3491 | H15: 8653
B16: 2nd Q. | D16: 297 | E16: 1280 | F16: 2647 | G16: 2417 | H16: 6641
B17: 3rd Q. | D17: 581 | E17: 1123 | F17: 5622 | G17: 3361 | H17: 10687
B18: 4th Q. | D18: 628 | E18: 837 | F18: 5203 | G18: 3696 | H18: 10364
A19: 2021 | B19: 1st Q. | D19: 690 | E19: 976 | F19: 5015 | G19: 4183 | H19: 10864
B20: 2nd Q. | D20: 733 | E20: 1016 | F20: 4494 | G20: 3790 | H20: 10033
B21: 3rd Q. | D21: 621 | E21: 891 | F21: 3487 | G21: 2832 | H21: 7831
B22: 4th Q. | D22: 572 | E22: 1104 | F22: 8194 | G22: 3488 | H22: 13358
A23: 2019 | B23: January | D23: 458 | E23: 644 | F23: 3043 | G23: 1189 | H23: =IF(SUM(C23:G23)=0,"",SUM(C23:G23)) -> 5334
B24: February | D24: 479 | E24: 269 | F24: 3123 | G24: 468 | H24: =IF(SUM(C24:G24)=0,"",SUM(C24:G24)) -> 4339
B25: March | D25: 413 | E25: 78 | F25: 4664 | G25: 694 | H25: =IF(SUM(C25:G25)=0,"",SUM(C25:G25)) -> 5849
B26: April | D26: 342 | E26: 273 | F26: 3360 | G26: 1551 | H26: =IF(SUM(C26:G26)=0,"",SUM(C26:G26)) -> 5526
B27: May | D27: 516 | E27: 854 | F27: 3330 | G27: 1840 | H27: =IF(SUM(C27:G27)=0,"",SUM(C27:G27)) -> 6540
B28: June | D28: 687 | E28: 1409 | F28: 7466 | G28: 5036 | H28: =IF(SUM(C28:G28)=0,"",SUM(C28:G28)) -> 14598
B29: July | D29: 510 | E29: 1696 | F29: 3494 | G29: 2508 | H29: =IF(SUM(C29:G29)=0,"",SUM(C29:G29)) -> 8208
B30: August | D30: 743 | E30: 766 | F30: 4465 | G30: 3575 | H30: =IF(SUM(C30:G30)=0,"",SUM(C30:G30)) -> 9549
B31: September | D31: 820 | E31: 1792 | F31: 3343 | G31: 3801 | H31: =IF(SUM(C31:G31)=0,"",SUM(C31:G31)) -> 9756
B32: October | D32: 732 | E32: 1088 | F32: 2677 | G32: 1625 | H32: =IF(SUM(C32:G32)=0,"",SUM(C32:G32)) -> 6122
B33: November | D33: 832 | E33: 839 | F33: 3469 | G33: 3953 | H33: =IF(SUM(C33:G33)=0,"",SUM(C33:G33)) -> 9093
B34: December | D34: 685 | E34: 1339 | F34: 6001 | G34: 1047 | H34: =IF(SUM(C34:G34)=0,"",SUM(C34:G34)) -> 9072
A35: 2020 | B35: January | D35: 457 | E35: 417 | F35: 2512 | G35: 1732 | H35: =IF(SUM(C35:G35)=0,"",SUM(C35:G35)) -> 5118
B36: February | D36: 638 | E36: 1122 | F36: 7496 | G36: 1300 | H36: =IF(SUM(C36:G36)=0,"",SUM(C36:G36)) -> 10556
B37: March | D37: 284 | E37: 295 | F37: 2283 | G37: 2770 | H37: =IF(SUM(C37:G37)=0,"",SUM(C37:G37)) -> 5632
B38: April | D38: 261 | E38: 607 | F38: 2112 | G38: 2092 | H38: =IF(SUM(C38:G38)=0,"",SUM(C38:G38)) -> 5072
B39: May | D39: 177 | E39: 1013 | F39: 3488 | G39: 3145 | H39: =IF(SUM(C39:G39)=0,"",SUM(C39:G39)) -> 7823
B40: June | D40: 397 | E40: 1848 | F40: 2417 | G40: 2319 | H40: =IF(SUM(C40:G40)=0,"",SUM(C40:G40)) -> 6981
B41: July | D41: 688 | E41: 381 | F41: 7530 | G41: 6623 | H41: =IF(SUM(C41:G41)=0,"",SUM(C41:G41)) -> 15222
B42: August | D42: 679 | E42: 1989 | F42: 3279 | G42: 4064 | H42: =IF(SUM(C42:G42)=0,"",SUM(C42:G42)) -> 10011
B43: September | D43: 435 | E43: 506 | F43: 5977 | G43: 2138 | H43: =IF(SUM(C43:G43)=0,"",SUM(C43:G43)) -> 9056
B44: October | D44: 541 | E44: 507 | F44: 2426 | G44: 1911 | H44: =IF(SUM(C44:G44)=0,"",SUM(C44:G44)) -> 5385
...

Sheet Table 7
A1: Table 7
A2: Dwelling Starts in Urban Centres1, Prairie Provinces, Seasonally Adjusted at Annual Rates
A6: Period | D6: Manitoba | E6: Saskatchewan | F6: Alberta | G6: Total
A7: 2019 2 | D7: 5935 | E7: 2055 | F7: 25958 | G7: 33948
A8: 2020 2 | D8: 6203 | E8: 2803 | F8: 23043 | G8: 32049
A9: 2019 | B9: 1st Q. | D9: 5428 | E9: 1603 | F9: 19922 | G9: 26953
B10: 2nd Q. | D10: 7614 | E10: 1950 | F10: 24734 | G10: 34298
B11: 3rd Q. | D11: 5201 | E11: 2506 | F11: 30175 | G11: 37882
B12: 4th Q. | D12: 5526 | E12: 2132 | F12: 28594 | G12: 36252
A13: 2020 | B13: 1st Q. | D13: 5319 | E13: 2314 | F13: 23534 | G13: 31167
B14: 2nd Q. | D14: 5637 | E14: 2053 | F14: 18174 | G14: 25864
B15: 3rd Q. | D15: 4793 | E15: 4009 | F15: 22620 | G15: 31422
B16: 4th Q. | D16: 9187 | E16: 2773 | F16: 28741 | G16: 40701
A17: 2021 | B17: 1st Q. | D17: 6565 | E17: 4463 | F17: 26877 | G17: 37905
B18: 2nd Q. | D18: 6967 | E18: 4261 | F18: 31446 | G18: 42674
B19: 3rd Q. | D19: 7094 | E19: 3523 | F19: 28864 | G19: 39481
B20: 4th Q. | D20: 5727 | E20: 2875 | F20: 35147 | G20: 43749
A21: 2019 | B21: January | D21: 6129 | E21: 2016 | F21: 22618 | G21: =IF(SUM(B21:F21)=0,"",SUM(B21:F21)) -> 30763
B22: February | D22: 4909 | E22: 1181 | F22: 18281 | G22: =IF(SUM(B22:F22)=0,"",SUM(B22:F22)) -> 24371
B23: March | D23: 5020 | E23: 1424 | F23: 17325 | G23: =IF(SUM(B23:F23)=0,"",SUM(B23:F23)) -> 23769
B24: April | D24: 5710 | E24: 1325 | F24: 24426 | G24: =IF(SUM(B24:F24)=0,"",SUM(B24:F24)) -> 31461
B25: May | D25: 8233 | E25: 2066 | F25: 21290 | G25: =IF(SUM(B25:F25)=0,"",SUM(B25:F25)) -> 31589
B26: June | D26: 9036 | E26: 2697 | F26: 30698 | G26: =IF(SUM(B26:F26)=0,"",SUM(B26:F26)) -> 42431
B27: July | D27: 5939 | E27: 1183 | F27: 28563 | G27: =IF(SUM(B27:F27)=0,"",SUM(B27:F27)) -> 35685
B28: August | D28: 5714 | E28: 2791 | F28: 29363 | G28: =IF(SUM(B28:F28)=0,"",SUM(B28:F28)) -> 37868
B29: September | D29: 3849 | E29: 3573 | F29: 32171 | G29: =IF(SUM(B29:F29)=0,"",SUM(B29:F29)) -> 39593
B30: October | D30: 6687 | E30: 2304 | F30: 22923 | G30: =IF(SUM(B30:F30)=0,"",SUM(B30:F30)) -> 31914
B31: November | D31: 5401 | E31: 1842 | F31: 25048 | G31: =IF(SUM(B31:F31)=0,"",SUM(B31:F31)) -> 32291
B32: December | D32: 4638 | E32: 2206 | F32: 37273 | G32: =IF(SUM(B32:F32)=0,"",SUM(B32:F32)) -> 44117
A33: 2020 | B33: January | D33: 6500 | E33: 3274 | F33: 19535 | G33: =IF(SUM(B33:F33)=0,"",SUM(B33:F33)) -> 29309
B34: February | D34: 4468 | E34: 1905 | F34: 18308 | G34: =IF(SUM(B34:F34)=0,"",SUM(B34:F34)) -> 24681
B35: March | D35: 4810 | E35: 1622 | F35: 31352 | G35: =IF(SUM(B35:F35)=0,"",SUM(B35:F35)) -> 37784
B36: April | D36: 6340 | E36: 2297 | F36: 22898 | G36: =IF(SUM(B36:F36)=0,"",SUM(B36:F36)) -> 31535
B37: May | D37: 3705 | E37: 1800 | F37: 18409 | G37: =IF(SUM(B37:F37)=0,"",SUM(B37:F37)) -> 23914
B38: June | D38: 6995 | E38: 2387 | F38: 14677 | G38: =IF(SUM(B38:F38)=0,"",SUM(B38:F38)) -> 24059
B39: July | D39: 6380 | E39: 7930 | F39: 22316 | G39: =IF(SUM(B39:F39)=0,"",SUM(B39:F39)) -> 36626
B40: August | D40: 4564 | E40: 2385 | F40: 19652 | G40: =IF(SUM(B40:F40)=0,"",SUM(B40:F40)) -> 26601
B41: September | D41: 3389 | E41: 1665 | F41: 25322 | G41: =IF(SUM(B41:F41)=0,"",SUM(B41:F41)) -> 30376
B42: October | D42: 9884 | E42: 2074 | F42: 31366 | G42: =IF(SUM(B42:F42)=0,"",SUM(B42:F42)) -> 43324
B43: November | D43: 11405 | E43: 3221 | F43: 25336 | G43: =IF(SUM(B43:F43)=0,"",SUM(B43:F43)) -> 39962
...

Sheet Table 8
A1: Table 8
A2: Dwelling Starts - Seasonally Adjusted at Annual Rates1
A5: Period | D5: St. John's | E5: Halifax | F5: Moncton | G5: Saint John | H5: Saguenay
A6: 2019 2 | D6: 480 | E6: 3143 | F6: 1242 | G6: 381 | H6: 452
A7: 2020 2 | D7: 418 | E7: 3249 | F7: 1708 | G7: 540 | H7: 535
A8: 2019 | B8: January | D8: 370 | E8: 2531 | F8: 28 | G8: 553 | H8: 123
B9: February | D9: 358 | E9: 2781 | F9: 133 | G9: 68 | H9: 313
B10: March | D10: 230 | E10: 4369 | F10: 315 | G10: 92 | H10: 178
B11: April | D11: 180 | E11: 2257 | F11: 1104 | G11: 88 | H11: 256
B12: May | D12: 445 | E12: 2431 | F12: 1375 | G12: 186 | H12: 522
B13: June | D13: 658 | E13: 6399 | F13: 2678 | G13: 1012 | H13: 537
B14: July | D14: 325 | E14: 2510 | F14: 1261 | G14: 210 | H14: 266
B15: August | D15: 507 | E15: 3570 | F15: 1759 | G15: 697 | H15: 350
B16: September | D16: 684 | E16: 2582 | F16: 2570 | G16: 780 | H16: 398
B17: October | D17: 560 | E17: 1434 | F17: 448 | G17: 466 | H17: 1332
B18: November | D18: 657 | E18: 2282 | F18: 2651 | G18: 186 | H18: 699
B19: December | D19: 500 | E19: 4393 | F19: 512 | G19: 33 | H19: 307
A20: 2020 | B20: January | D20: 385 | E20: 1173 | F20: 240 | G20: 398 | H20: 1118
B21: February | D21: 349 | E21: 5705 | F21: 361 | G21: 653 | H21: 317
B22: March | D22: 188 | E22: 1295 | F22: 762 | G22: 853 | H22: 3
B23: April | D23: 171 | E23: 1458 | F23: 1274 | G23: 210 | H23: 0
B24: May | D24: 127 | E24: 2712 | F24: 2011 | G24: 185 | H24: 664
B25: June | D25: 310 | E25: 1483 | F25: 1331 | G25: 471 | H25: 469
B26: July | D26: 575 | E26: 6574 | F26: 4601 | G26: 1089 | H26: 938
B27: August | D27: 574 | E27: 2048 | F27: 1686 | G27: 416 | H27: 144
B28: September | D28: 338 | E28: 5231 | F28: 685 | G28: 725 | H28: 393
B29: October | D29: 469 | E29: 1317 | F29: 946 | G29: 212 | H29: 671
B30: November | D30: 728 | E30: 6719 | F30: 2365 | G30: 1072 | H30: 583
B31: December | D31: 466 | E31: 3936 | F31: 4295 | G31: 315 | H31: 1037
A32: 2021 | B32: January | D32: 541 | E32: 4635 | F32: 1415 | G32: 383 | H32: 1793
B33: February | D33: 405 | E33: 3097 | F33: 431 | G33: 318 | H33: 279
B34: March | D34: 692 | E34: 2665 | F34: 303 | G34: 265 | H34: 483
B35: April | D35: 743 | E35: 1549 | F35: 1780 | G35: 1076 | H35: 690
B36: May | D36: 728 | E36: 6815 | F36: 3576 | G36: 338 | H36: 696
B37: June | D37: 528 | E37: 166 | F37: 1957 | G37: 354 | H37: 631
B38: July | D38: 608 | E38: 3360 | F38: 1561 | G38: 1301 | H38: 401
B39: August | D39: 437 | E39: 425 | F39: 2437 | G39: 292 | H39: 620
B40: September | D40: 538 | E40: 2606 | F40: 628 | G40: 856 | H40: 247
B41: October | D41: 599 | E41: 8183 | F41: 1877 | G41: 398 | H41: 480
B42: November | D42: 302 | E42: 5505 | F42: 3267 | G42: 171 | H42: 937
...

Sheet Table 9
A1: Table 9 - Tableau 9
A2: Dwelling Starts - Seasonally Adjusted at Annual Rates1
A5: Period | D5: Québec | E5: Sherbrooke | F5: Trois-Rivières | G5: Montréal | H5: Gatineau
A6: 2019 2 | D6: 6203 | E6: 1880 | F6: 640 | G6: 25112 | H6: 3421
A7: 2020 2 | D7: 6713 | E7: 2264 | F7: 662 | G7: 27274 | H7: 3084
A8: 2019 | B8: January | D8: 1543 | E8: 141 | F8: 246 | G8: 19342 | H8: 789
B9: February | D9: 1546 | E9: 3840 | F9: 368 | G9: 14945 | H9: 1746
B10: March | D10: 2799 | E10: 3915 | F10: 447 | G10: 31503 | H10: 5527
B11: April | D11: 4027 | E11: 1466 | F11: 668 | G11: 29190 | H11: 5069
B12: May | D12: 8799 | E12: 1439 | F12: 632 | G12: 25638 | H12: 5979
B13: June | D13: 11633 | E13: 871 | F13: 320 | G13: 40304 | H13: 1490
B14: July | D14: 8869 | E14: 1000 | F14: 586 | G14: 24723 | H14: 3453
B15: August | D15: 6207 | E15: 719 | F15: 423 | G15: 25562 | H15: 1022
B16: September | D16: 11738 | E16: 2889 | F16: 914 | G16: 18648 | H16: 2563
B17: October | D17: 6024 | E17: 1461 | F17: 1410 | G17: 31301 | H17: 6275
B18: November | D18: 7824 | E18: 2102 | F18: 734 | G18: 20723 | H18: 3768
B19: December | D19: 3143 | E19: 2366 | F19: 615 | G19: 18992 | H19: 3344
A20: 2020 | B20: January | D20: 4690 | E20: 2724 | F20: 305 | G20: 28508 | H20: 3047
B21: February | D21: 2514 | E21: 754 | F21: 527 | G21: 19513 | H21: 5283
B22: March | D22: 5478 | E22: 3452 | F22: 215 | G22: 17945 | H22: 1460
B23: April | D23: 0 | E23: 0 | F23: 0 | G23: 0 | H23: 0
B24: May | D24: 11509 | E24: 1811 | F24: 1693 | G24: 33168 | H24: 3904
B25: June | D25: 11348 | E25: 4149 | F25: 989 | G25: 39518 | H25: 3646
B26: July | D26: 6671 | E26: 1229 | F26: 909 | G26: 35597 | H26: 2621
B27: August | D27: 9582 | E27: 1936 | F27: 348 | G27: 27009 | H27: 1870
B28: September | D28: 8901 | E28: 2285 | F28: 501 | G28: 32695 | H28: 4391
B29: October | D29: 9331 | E29: 5633 | F29: 955 | G29: 24525 | H29: 1931
B30: November | D30: 5220 | E30: 1534 | F30: 858 | G30: 36134 | H30: 4926
B31: December | D31: 5443 | E31: 1760 | F31: 579 | G31: 34114 | H31: 3611
A32: 2021 | B32: January | D32: 13654 | E32: 2393 | F32: 667 | G32: 36894 | H32: 3356
B33: February | D33: 3744 | E33: 3247 | F33: 484 | G33: 39909 | H33: 1593
B34: March | D34: 7065 | E34: 4053 | F34: 1285 | G34: 30629 | H34: 2364
B35: April | D35: 7259 | E35: 2807 | F35: 828 | G35: 39353 | H35: 7160
B36: May | D36: 11473 | E36: 2370 | F36: 872 | G36: 27970 | H36: 5555
B37: June | D37: 16966 | E37: 2615 | F37: 1282 | G37: 39010 | H37: 2342
B38: July | D38: 16655 | E38: 1439 | F38: 1308 | G38: 30528 | H38: 1361
B39: August | D39: 2178 | E39: 1879 | F39: 437 | G39: 26812 | H39: 742
B40: September | D40: 9116 | E40: 3050 | F40: 1695 | G40: 34032 | H40: 6837
B41: October | D41: 7929 | E41: 3093 | F41: 1086 | G41: 28280 | H41: 3637
B42: November | D42: 9916 | E42: 2767 | F42: 1668 | G42: 36212 | H42: 2396
...

Sheet Table 10
A1: Table 10
A2: Dwelling Starts - Seasonally Adjusted at Annual Rates1
A5: Period | D5: Ottawa | E5: Kingston | F5: Belleville | G5: Peterborough | H5: Oshawa | I5: Toronto
A6: 2019 2 | D6: 7782 | E6: 1256 | F6: 591 | G6: 499 | H6: 1703 | I6: 30462
A7: 2020 2 | D7: 9950 | E7: 1041 | F7: 673 | G7: 528 | H7: 2666 | I7: 38587
A8: 2019 | B8: January | D8: 3280 | E8: 2598 | F8: 366 | G8: 144 | H8: 813 | I8: 39433
B9: February | D9: 9469 | E9: 57 | F9: 241 | G9: 123 | H9: 402 | I9: 20820
B10: March | D10: 3844 | E10: 448 | F10: 592 | G10: 973 | H10: 809 | I10: 31881
B11: April | D11: 6349 | E11: 548 | F11: 386 | G11: 381 | H11: 426 | I11: 37930
B12: May | D12: 7455 | E12: 477 | F12: 608 | G12: 1288 | H12: 4078 | I12: 20127
B13: June | D13: 9180 | E13: 411 | F13: 814 | G13: 229 | H13: 2446 | I13: 34704
B14: July | D14: 6486 | E14: 994 | F14: 536 | G14: 1260 | H14: 1560 | I14: 32238
B15: August | D15: 6814 | E15: 3119 | F15: 748 | G15: 469 | H15: 1189 | I15: 36383
B16: September | D16: 14904 | E16: 4743 | F16: 647 | G16: 467 | H16: 1461 | I16: 32729
B17: October | D17: 7372 | E17: 647 | F17: 489 | G17: 567 | H17: 895 | I17: 32160
B18: November | D18: 10788 | E18: 357 | F18: 653 | G18: 144 | H18: 1791 | I18: 24001
B19: December | D19: 6930 | E19: 739 | F19: 866 | G19: 117 | H19: 3583 | I19: 22092
A20: 2020 | B20: January | D20: 5929 | E20: 310 | F20: 2066 | G20: 96 | H20: 824 | I20: 32367
B21: February | D21: 11760 | E21: 398 | F21: 624 | G21: 125 | H21: 2361 | I21: 31331
B22: March | D22: 6849 | E22: 381 | F22: 438 | G22: 1765 | H22: 1375 | I22: 24461
B23: April | D23: 10381 | E23: 489 | F23: 657 | G23: 534 | H23: 1145 | I23: 60732
B24: May | D24: 7787 | E24: 2530 | F24: 294 | G24: 366 | H24: 1881 | I24: 29693
B25: June | D25: 7266 | E25: 800 | F25: 371 | G25: 137 | H25: 1687 | I25: 39892
B26: July | D26: 8019 | E26: 1230 | F26: 606 | G26: 206 | H26: 1644 | I26: 47773
B27: August | D27: 18860 | E27: 960 | F27: 430 | G27: 1043 | H27: 8576 | I27: 61774
B28: September | D28: 12900 | E28: 2623 | F28: 594 | G28: 199 | H28: 3640 | I28: 33171
B29: October | D29: 8437 | E29: 931 | F29: 1233 | G29: 1168 | H29: 3846 | I29: 36284
B30: November | D30: 12578 | E30: 1176 | F30: 551 | G30: 499 | H30: 2734 | I30: 34415
B31: December | D31: 9426 | E31: 699 | F31: 626 | G31: 284 | H31: 2281 | I31: 31654
A32: 2021 | B32: January | D32: 7359 | E32: 1521 | F32: 333 | G32: 454 | H32: 2157 | I32: 36774
